<robot
  name="moveo_urdf_5">
    <link
    name="base_link">
    <inertial>
      <origin
        xyz="0.034155 -0.20591 -0.049641"
        rpy="0 0 0" />
      <mass
        value="8.0643" />
      <inertia
        ixx="0.11291"
        ixy="0.00066071"
        ixz="-0.00030472"
        iyy="0.089946"
        iyz="0.011461"
        izz="0.19187" />
    </inertial>
    
    <collision>
      <origin
        xyz="0 0 0"
        rpy="0 0 0" />
      <!-- <geometry>
        <mesh
          filename="package://moveo_urdf_4/meshes/base_link.STL" />
      </geometry> -->
    </collision>
  </link>
  <link
    name="Link_1">
    <inertial>
      <origin
        xyz="4.0186E-05 0.090634 0.00010221"
        rpy="0 0 0" />
      <mass
        value="4.2526" />
      <inertia
        ixx="0.0034071"
        ixy="8.9041E-06"
        ixz="1.179E-07"
        iyy="0.018642"
        iyz="-3.6544E-06"
        izz="0.021987" />
    </inertial>
   
    <collision>
      <origin
        xyz="0 0 0"
        rpy="0 0 0" />
      <!-- <geometry>
        <mesh
          filename="package://moveo_urdf_4/meshes/Link_1.STL" />
      </geometry> -->
    </collision>
  </link>
  <joint
    name="Joint_1"
    type="revolute">
    <origin
      xyz="0 -0.2425 0"
      rpy="1.5708 9.5417E-17 2.7766" />
    <parent
      link="base_link" />
    <child
      link="Link_1" />
    <axis
      xyz="0 1 0" />
    <limit
      lower="-1"
      upper="1"
      effort="5"
      velocity="1" />
  </joint>
  <link
    name="Link_2">
    <inertial>
      <origin
        xyz="2.2815E-05 0.0017616 -0.080002"
        rpy="0 0 0" />
      <mass
        value="1.9323" />
      <inertia
        ixx="0.012138"
        ixy="-3.5576E-06"
        ixz="-9.0632E-06"
        iyy="0.011445"
        iyz="0.00014273"
        izz="0.00070271" />
    </inertial>
    
    <collision>
      <origin
        xyz="0 0 0"
        rpy="0 0 0" />
      <!-- <geometry>
        <mesh
          filename="package://moveo_urdf_5/meshes/Link_2.STL" />
      </geometry> -->
    </collision>
  </link>
  <joint
    name="Joint_2"
    type="revolute">
    <origin
      xyz="0 0.18264 0"
      rpy="-3.1416 0.95134 1.5708" />
    <parent
      link="Link_1" />
    <child
      link="Link_2" />
    <axis
      xyz="0 -1 0" />
    <limit
      lower="-1"
      upper="1"
      effort="5"
      velocity="1" />
  </joint>
  <link
    name="Link_3">
    <inertial>
      <origin
        xyz="0.05095 -0.00039084 -0.00045591"
        rpy="0 0 0" />
      <mass
        value="1.1381" />
      <inertia
        ixx="0.00023572"
        ixy="-3.8425E-06"
        ixz="4.1286E-06"
        iyy="0.00029123"
        iyz="-1.0387E-07"
        izz="0.00052457" />
    </inertial>
    
    <collision>
      <origin
        xyz="0 0 0"
        rpy="0 0 0" />
      <!-- <geometry>
        <mesh
          filename="package://moveo_urdf_5/meshes/Link_3.STL" />
      </geometry> -->
    </collision>
  </link>
  <joint
    name="Joint_3"
    type="revolute">
    <origin
      xyz="0 0 -0.22112"
      rpy="-3.1416 0.98126 -3.1416" />
    <parent
      link="Link_2" />
    <child
      link="Link_3" />
    <axis
      xyz="0 -1 0" />
    <limit
      lower="-1"
      upper="1"
      effort="5"
      velocity="1" />
  </joint>
  <link
    name="Link_4">
    <inertial>
      <origin
        xyz="-0.0027417 0.0025097 0.012864"
        rpy="0 0 0" />
      <mass
        value="0.62964" />
      <inertia
        ixx="0.0001717"
        ixy="1.3446E-06"
        ixz="8.5164E-06"
        iyy="0.00010506"
        iyz="5.1412E-05"
        izz="7.8944E-05" />
    </inertial>
    
    <collision>
      <origin
        xyz="0 0 0"
        rpy="0 0 0" />
      <geometry>
        <mesh
          filename="package://moveo_urdf_5/meshes/Link_4.STL" />
      </geometry>
    </collision>
  </link>
  <joint
    name="Joint_4"
    type="revolute">
    <origin
      xyz="0.16988 -0.00099213 0"
      rpy="3.1416 -1.2279 1.5708" />
    <parent
      link="Link_3" />
    <child
      link="Link_4" />
    <axis
      xyz="0.010353 -0.99993 -0.0059382" />
    <limit
      lower="-1"
      upper="1"
      effort="5"
      velocity="1" />
  </joint>
  <link
    name="Link_5">
    <inertial>
      <origin
        xyz="-0.011366 0.00012239 0.0078967"
        rpy="0 0 0" />
      <mass
        value="0.19875" />
      <inertia
        ixx="6.2676E-05"
        ixy="4.2551E-06"
        ixz="4.0215E-05"
        iyy="9.7792E-05"
        iyz="8.5888E-07"
        izz="9.5807E-05" />
    </inertial>
    
    <collision>
      <origin
        xyz="0 0 0"
        rpy="0 0 0" />
      <!-- <geometry>
        <mesh
          filename="package://moveo_urdf_5/meshes/Link_5.STL" />
      </geometry> -->
    </collision>
  </link>
  <joint
    name="Joint_5"
    type="revolute">
    <origin
      xyz="-0.0021346 0.053041 0.0016936"
      rpy="-1.5639 -0.091135 -0.00062919" />
    <parent
      link="Link_4" />
    <child
      link="Link_5" />
    <axis
      xyz="0 1 0" />
    <limit
      lower="-1"
      upper="1"
      effort="5"
      velocity="1" />
  </joint>
</robot>